{
 "cells": [
  {
   "cell_type": "code",
   "execution_count": 3,
   "id": "ca302e91",
   "metadata": {},
   "outputs": [
    {
     "name": "stderr",
     "output_type": "stream",
     "text": [
      "c:\\Users\\PHIL\\AppData\\Local\\Programs\\Python\\Python312\\Lib\\site-packages\\keras\\src\\layers\\convolutional\\base_conv.py:107: UserWarning: Do not pass an `input_shape`/`input_dim` argument to a layer. When using Sequential models, prefer using an `Input(shape)` object as the first layer in the model instead.\n",
      "  super().__init__(activity_regularizer=activity_regularizer, **kwargs)\n",
      "c:\\Users\\PHIL\\AppData\\Local\\Programs\\Python\\Python312\\Lib\\site-packages\\keras\\src\\layers\\convolutional\\base_conv.py:107: UserWarning: Do not pass an `input_shape`/`input_dim` argument to a layer. When using Sequential models, prefer using an `Input(shape)` object as the first layer in the model instead.\n",
      "  super().__init__(activity_regularizer=activity_regularizer, **kwargs)\n",
      "c:\\Users\\PHIL\\AppData\\Local\\Programs\\Python\\Python312\\Lib\\site-packages\\keras\\src\\layers\\convolutional\\base_conv.py:107: UserWarning: Do not pass an `input_shape`/`input_dim` argument to a layer. When using Sequential models, prefer using an `Input(shape)` object as the first layer in the model instead.\n",
      "  super().__init__(activity_regularizer=activity_regularizer, **kwargs)\n",
      "c:\\Users\\PHIL\\AppData\\Local\\Programs\\Python\\Python312\\Lib\\site-packages\\keras\\src\\layers\\convolutional\\base_conv.py:107: UserWarning: Do not pass an `input_shape`/`input_dim` argument to a layer. When using Sequential models, prefer using an `Input(shape)` object as the first layer in the model instead.\n",
      "  super().__init__(activity_regularizer=activity_regularizer, **kwargs)\n",
      "c:\\Users\\PHIL\\AppData\\Local\\Programs\\Python\\Python312\\Lib\\site-packages\\keras\\src\\layers\\convolutional\\base_conv.py:107: UserWarning: Do not pass an `input_shape`/`input_dim` argument to a layer. When using Sequential models, prefer using an `Input(shape)` object as the first layer in the model instead.\n",
      "  super().__init__(activity_regularizer=activity_regularizer, **kwargs)\n",
      "c:\\Users\\PHIL\\AppData\\Local\\Programs\\Python\\Python312\\Lib\\site-packages\\keras\\src\\layers\\convolutional\\base_conv.py:107: UserWarning: Do not pass an `input_shape`/`input_dim` argument to a layer. When using Sequential models, prefer using an `Input(shape)` object as the first layer in the model instead.\n",
      "  super().__init__(activity_regularizer=activity_regularizer, **kwargs)\n",
      "c:\\Users\\PHIL\\AppData\\Local\\Programs\\Python\\Python312\\Lib\\site-packages\\keras\\src\\layers\\convolutional\\base_conv.py:107: UserWarning: Do not pass an `input_shape`/`input_dim` argument to a layer. When using Sequential models, prefer using an `Input(shape)` object as the first layer in the model instead.\n",
      "  super().__init__(activity_regularizer=activity_regularizer, **kwargs)\n",
      "c:\\Users\\PHIL\\AppData\\Local\\Programs\\Python\\Python312\\Lib\\site-packages\\keras\\src\\layers\\convolutional\\base_conv.py:107: UserWarning: Do not pass an `input_shape`/`input_dim` argument to a layer. When using Sequential models, prefer using an `Input(shape)` object as the first layer in the model instead.\n",
      "  super().__init__(activity_regularizer=activity_regularizer, **kwargs)\n",
      "c:\\Users\\PHIL\\AppData\\Local\\Programs\\Python\\Python312\\Lib\\site-packages\\keras\\src\\layers\\convolutional\\base_conv.py:107: UserWarning: Do not pass an `input_shape`/`input_dim` argument to a layer. When using Sequential models, prefer using an `Input(shape)` object as the first layer in the model instead.\n",
      "  super().__init__(activity_regularizer=activity_regularizer, **kwargs)\n",
      "c:\\Users\\PHIL\\AppData\\Local\\Programs\\Python\\Python312\\Lib\\site-packages\\keras\\src\\layers\\convolutional\\base_conv.py:107: UserWarning: Do not pass an `input_shape`/`input_dim` argument to a layer. When using Sequential models, prefer using an `Input(shape)` object as the first layer in the model instead.\n",
      "  super().__init__(activity_regularizer=activity_regularizer, **kwargs)\n",
      "c:\\Users\\PHIL\\AppData\\Local\\Programs\\Python\\Python312\\Lib\\site-packages\\keras\\src\\layers\\convolutional\\base_conv.py:107: UserWarning: Do not pass an `input_shape`/`input_dim` argument to a layer. When using Sequential models, prefer using an `Input(shape)` object as the first layer in the model instead.\n",
      "  super().__init__(activity_regularizer=activity_regularizer, **kwargs)\n",
      "c:\\Users\\PHIL\\AppData\\Local\\Programs\\Python\\Python312\\Lib\\site-packages\\keras\\src\\layers\\convolutional\\base_conv.py:107: UserWarning: Do not pass an `input_shape`/`input_dim` argument to a layer. When using Sequential models, prefer using an `Input(shape)` object as the first layer in the model instead.\n",
      "  super().__init__(activity_regularizer=activity_regularizer, **kwargs)\n",
      "c:\\Users\\PHIL\\AppData\\Local\\Programs\\Python\\Python312\\Lib\\site-packages\\keras\\src\\layers\\convolutional\\base_conv.py:107: UserWarning: Do not pass an `input_shape`/`input_dim` argument to a layer. When using Sequential models, prefer using an `Input(shape)` object as the first layer in the model instead.\n",
      "  super().__init__(activity_regularizer=activity_regularizer, **kwargs)\n",
      "c:\\Users\\PHIL\\AppData\\Local\\Programs\\Python\\Python312\\Lib\\site-packages\\keras\\src\\layers\\convolutional\\base_conv.py:107: UserWarning: Do not pass an `input_shape`/`input_dim` argument to a layer. When using Sequential models, prefer using an `Input(shape)` object as the first layer in the model instead.\n",
      "  super().__init__(activity_regularizer=activity_regularizer, **kwargs)\n",
      "c:\\Users\\PHIL\\AppData\\Local\\Programs\\Python\\Python312\\Lib\\site-packages\\keras\\src\\layers\\convolutional\\base_conv.py:107: UserWarning: Do not pass an `input_shape`/`input_dim` argument to a layer. When using Sequential models, prefer using an `Input(shape)` object as the first layer in the model instead.\n",
      "  super().__init__(activity_regularizer=activity_regularizer, **kwargs)\n",
      "c:\\Users\\PHIL\\AppData\\Local\\Programs\\Python\\Python312\\Lib\\site-packages\\sklearn\\model_selection\\_validation.py:540: FitFailedWarning: \n",
      "12 fits failed out of a total of 15.\n",
      "The score on these train-test partitions for these parameters will be set to nan.\n",
      "If these failures are not expected, you can try to debug them by setting error_score='raise'.\n",
      "\n",
      "Below are more details about the failures:\n",
      "--------------------------------------------------------------------------------\n",
      "1 fits failed with the following error:\n",
      "Traceback (most recent call last):\n",
      "  File \"c:\\Users\\PHIL\\AppData\\Local\\Programs\\Python\\Python312\\Lib\\site-packages\\sklearn\\model_selection\\_validation.py\", line 888, in _fit_and_score\n",
      "    estimator.fit(X_train, y_train, **fit_params)\n",
      "  File \"c:\\Users\\PHIL\\AppData\\Local\\Programs\\Python\\Python312\\Lib\\site-packages\\scikeras\\wrappers.py\", line 770, in fit\n",
      "    self._fit(\n",
      "  File \"c:\\Users\\PHIL\\AppData\\Local\\Programs\\Python\\Python312\\Lib\\site-packages\\scikeras\\wrappers.py\", line 938, in _fit\n",
      "    self._fit_keras_model(\n",
      "  File \"c:\\Users\\PHIL\\AppData\\Local\\Programs\\Python\\Python312\\Lib\\site-packages\\scikeras\\wrappers.py\", line 535, in _fit_keras_model\n",
      "    hist = self.model_.fit(x=X, y=y, **fit_args)\n",
      "           ^^^^^^^^^^^^^^^^^^^^^^^^^^^^^^^^^^^^^\n",
      "  File \"c:\\Users\\PHIL\\AppData\\Local\\Programs\\Python\\Python312\\Lib\\site-packages\\keras\\src\\utils\\traceback_utils.py\", line 122, in error_handler\n",
      "    raise e.with_traceback(filtered_tb) from None\n",
      "  File \"c:\\Users\\PHIL\\AppData\\Local\\Programs\\Python\\Python312\\Lib\\site-packages\\keras\\src\\utils\\traceback_utils.py\", line 124, in error_handler\n",
      "    del filtered_tb\n",
      "        ^^^^^^^^^^^\n",
      "ValueError: Exception encountered when calling Conv1D.call().\n",
      "\n",
      "\u001b[1mNegative dimension size caused by subtracting 2 from 1 for '{{node sequential_1/conv1d_1/convolution}} = Conv2D[T=DT_FLOAT, data_format=\"NHWC\", dilations=[1, 1, 1, 1], explicit_paddings=[], padding=\"VALID\", strides=[1, 1, 1, 1], use_cudnn_on_gpu=true](sequential_1/conv1d_1/convolution/ExpandDims, sequential_1/conv1d_1/convolution/ExpandDims_1)' with input shapes: [?,1,1,3], [1,2,3,32].\u001b[0m\n",
      "\n",
      "Arguments received by Conv1D.call():\n",
      "  â€¢ inputs=tf.Tensor(shape=(None, 1, 3), dtype=float32)\n",
      "\n",
      "--------------------------------------------------------------------------------\n",
      "1 fits failed with the following error:\n",
      "Traceback (most recent call last):\n",
      "  File \"c:\\Users\\PHIL\\AppData\\Local\\Programs\\Python\\Python312\\Lib\\site-packages\\sklearn\\model_selection\\_validation.py\", line 888, in _fit_and_score\n",
      "    estimator.fit(X_train, y_train, **fit_params)\n",
      "  File \"c:\\Users\\PHIL\\AppData\\Local\\Programs\\Python\\Python312\\Lib\\site-packages\\scikeras\\wrappers.py\", line 770, in fit\n",
      "    self._fit(\n",
      "  File \"c:\\Users\\PHIL\\AppData\\Local\\Programs\\Python\\Python312\\Lib\\site-packages\\scikeras\\wrappers.py\", line 938, in _fit\n",
      "    self._fit_keras_model(\n",
      "  File \"c:\\Users\\PHIL\\AppData\\Local\\Programs\\Python\\Python312\\Lib\\site-packages\\scikeras\\wrappers.py\", line 535, in _fit_keras_model\n",
      "    hist = self.model_.fit(x=X, y=y, **fit_args)\n",
      "           ^^^^^^^^^^^^^^^^^^^^^^^^^^^^^^^^^^^^^\n",
      "  File \"c:\\Users\\PHIL\\AppData\\Local\\Programs\\Python\\Python312\\Lib\\site-packages\\keras\\src\\utils\\traceback_utils.py\", line 122, in error_handler\n",
      "    raise e.with_traceback(filtered_tb) from None\n",
      "  File \"c:\\Users\\PHIL\\AppData\\Local\\Programs\\Python\\Python312\\Lib\\site-packages\\keras\\src\\utils\\traceback_utils.py\", line 124, in error_handler\n",
      "    del filtered_tb\n",
      "        ^^^^^^^^^^^\n",
      "ValueError: Exception encountered when calling Conv1D.call().\n",
      "\n",
      "\u001b[1mNegative dimension size caused by subtracting 2 from 1 for '{{node sequential_1_1/conv1d_1_1/convolution}} = Conv2D[T=DT_FLOAT, data_format=\"NHWC\", dilations=[1, 1, 1, 1], explicit_paddings=[], padding=\"VALID\", strides=[1, 1, 1, 1], use_cudnn_on_gpu=true](sequential_1_1/conv1d_1_1/convolution/ExpandDims, sequential_1_1/conv1d_1_1/convolution/ExpandDims_1)' with input shapes: [?,1,1,3], [1,2,3,32].\u001b[0m\n",
      "\n",
      "Arguments received by Conv1D.call():\n",
      "  â€¢ inputs=tf.Tensor(shape=(None, 1, 3), dtype=float32)\n",
      "\n",
      "--------------------------------------------------------------------------------\n",
      "1 fits failed with the following error:\n",
      "Traceback (most recent call last):\n",
      "  File \"c:\\Users\\PHIL\\AppData\\Local\\Programs\\Python\\Python312\\Lib\\site-packages\\sklearn\\model_selection\\_validation.py\", line 888, in _fit_and_score\n",
      "    estimator.fit(X_train, y_train, **fit_params)\n",
      "  File \"c:\\Users\\PHIL\\AppData\\Local\\Programs\\Python\\Python312\\Lib\\site-packages\\scikeras\\wrappers.py\", line 770, in fit\n",
      "    self._fit(\n",
      "  File \"c:\\Users\\PHIL\\AppData\\Local\\Programs\\Python\\Python312\\Lib\\site-packages\\scikeras\\wrappers.py\", line 938, in _fit\n",
      "    self._fit_keras_model(\n",
      "  File \"c:\\Users\\PHIL\\AppData\\Local\\Programs\\Python\\Python312\\Lib\\site-packages\\scikeras\\wrappers.py\", line 535, in _fit_keras_model\n",
      "    hist = self.model_.fit(x=X, y=y, **fit_args)\n",
      "           ^^^^^^^^^^^^^^^^^^^^^^^^^^^^^^^^^^^^^\n",
      "  File \"c:\\Users\\PHIL\\AppData\\Local\\Programs\\Python\\Python312\\Lib\\site-packages\\keras\\src\\utils\\traceback_utils.py\", line 122, in error_handler\n",
      "    raise e.with_traceback(filtered_tb) from None\n",
      "  File \"c:\\Users\\PHIL\\AppData\\Local\\Programs\\Python\\Python312\\Lib\\site-packages\\keras\\src\\utils\\traceback_utils.py\", line 124, in error_handler\n",
      "    del filtered_tb\n",
      "        ^^^^^^^^^^^\n",
      "ValueError: Exception encountered when calling Conv1D.call().\n",
      "\n",
      "\u001b[1mNegative dimension size caused by subtracting 2 from 1 for '{{node sequential_2_1/conv1d_2_1/convolution}} = Conv2D[T=DT_FLOAT, data_format=\"NHWC\", dilations=[1, 1, 1, 1], explicit_paddings=[], padding=\"VALID\", strides=[1, 1, 1, 1], use_cudnn_on_gpu=true](sequential_2_1/conv1d_2_1/convolution/ExpandDims, sequential_2_1/conv1d_2_1/convolution/ExpandDims_1)' with input shapes: [?,1,1,3], [1,2,3,32].\u001b[0m\n",
      "\n",
      "Arguments received by Conv1D.call():\n",
      "  â€¢ inputs=tf.Tensor(shape=(None, 1, 3), dtype=float32)\n",
      "\n",
      "--------------------------------------------------------------------------------\n",
      "1 fits failed with the following error:\n",
      "Traceback (most recent call last):\n",
      "  File \"c:\\Users\\PHIL\\AppData\\Local\\Programs\\Python\\Python312\\Lib\\site-packages\\sklearn\\model_selection\\_validation.py\", line 888, in _fit_and_score\n",
      "    estimator.fit(X_train, y_train, **fit_params)\n",
      "  File \"c:\\Users\\PHIL\\AppData\\Local\\Programs\\Python\\Python312\\Lib\\site-packages\\scikeras\\wrappers.py\", line 770, in fit\n",
      "    self._fit(\n",
      "  File \"c:\\Users\\PHIL\\AppData\\Local\\Programs\\Python\\Python312\\Lib\\site-packages\\scikeras\\wrappers.py\", line 938, in _fit\n",
      "    self._fit_keras_model(\n",
      "  File \"c:\\Users\\PHIL\\AppData\\Local\\Programs\\Python\\Python312\\Lib\\site-packages\\scikeras\\wrappers.py\", line 535, in _fit_keras_model\n",
      "    hist = self.model_.fit(x=X, y=y, **fit_args)\n",
      "           ^^^^^^^^^^^^^^^^^^^^^^^^^^^^^^^^^^^^^\n",
      "  File \"c:\\Users\\PHIL\\AppData\\Local\\Programs\\Python\\Python312\\Lib\\site-packages\\keras\\src\\utils\\traceback_utils.py\", line 122, in error_handler\n",
      "    raise e.with_traceback(filtered_tb) from None\n",
      "  File \"c:\\Users\\PHIL\\AppData\\Local\\Programs\\Python\\Python312\\Lib\\site-packages\\keras\\src\\utils\\traceback_utils.py\", line 124, in error_handler\n",
      "    del filtered_tb\n",
      "        ^^^^^^^^^^^\n",
      "ValueError: Exception encountered when calling Conv1D.call().\n",
      "\n",
      "\u001b[1mNegative dimension size caused by subtracting 2 from 1 for '{{node sequential_3_1/conv1d_3_1/convolution}} = Conv2D[T=DT_FLOAT, data_format=\"NHWC\", dilations=[1, 1, 1, 1], explicit_paddings=[], padding=\"VALID\", strides=[1, 1, 1, 1], use_cudnn_on_gpu=true](sequential_3_1/conv1d_3_1/convolution/ExpandDims, sequential_3_1/conv1d_3_1/convolution/ExpandDims_1)' with input shapes: [?,1,1,3], [1,2,3,128].\u001b[0m\n",
      "\n",
      "Arguments received by Conv1D.call():\n",
      "  â€¢ inputs=tf.Tensor(shape=(None, 1, 3), dtype=float32)\n",
      "\n",
      "--------------------------------------------------------------------------------\n",
      "1 fits failed with the following error:\n",
      "Traceback (most recent call last):\n",
      "  File \"c:\\Users\\PHIL\\AppData\\Local\\Programs\\Python\\Python312\\Lib\\site-packages\\sklearn\\model_selection\\_validation.py\", line 888, in _fit_and_score\n",
      "    estimator.fit(X_train, y_train, **fit_params)\n",
      "  File \"c:\\Users\\PHIL\\AppData\\Local\\Programs\\Python\\Python312\\Lib\\site-packages\\scikeras\\wrappers.py\", line 770, in fit\n",
      "    self._fit(\n",
      "  File \"c:\\Users\\PHIL\\AppData\\Local\\Programs\\Python\\Python312\\Lib\\site-packages\\scikeras\\wrappers.py\", line 938, in _fit\n",
      "    self._fit_keras_model(\n",
      "  File \"c:\\Users\\PHIL\\AppData\\Local\\Programs\\Python\\Python312\\Lib\\site-packages\\scikeras\\wrappers.py\", line 535, in _fit_keras_model\n",
      "    hist = self.model_.fit(x=X, y=y, **fit_args)\n",
      "           ^^^^^^^^^^^^^^^^^^^^^^^^^^^^^^^^^^^^^\n",
      "  File \"c:\\Users\\PHIL\\AppData\\Local\\Programs\\Python\\Python312\\Lib\\site-packages\\keras\\src\\utils\\traceback_utils.py\", line 122, in error_handler\n",
      "    raise e.with_traceback(filtered_tb) from None\n",
      "  File \"c:\\Users\\PHIL\\AppData\\Local\\Programs\\Python\\Python312\\Lib\\site-packages\\keras\\src\\utils\\traceback_utils.py\", line 124, in error_handler\n",
      "    del filtered_tb\n",
      "        ^^^^^^^^^^^\n",
      "ValueError: Exception encountered when calling Conv1D.call().\n",
      "\n",
      "\u001b[1mNegative dimension size caused by subtracting 2 from 1 for '{{node sequential_4_1/conv1d_4_1/convolution}} = Conv2D[T=DT_FLOAT, data_format=\"NHWC\", dilations=[1, 1, 1, 1], explicit_paddings=[], padding=\"VALID\", strides=[1, 1, 1, 1], use_cudnn_on_gpu=true](sequential_4_1/conv1d_4_1/convolution/ExpandDims, sequential_4_1/conv1d_4_1/convolution/ExpandDims_1)' with input shapes: [?,1,1,3], [1,2,3,128].\u001b[0m\n",
      "\n",
      "Arguments received by Conv1D.call():\n",
      "  â€¢ inputs=tf.Tensor(shape=(None, 1, 3), dtype=float32)\n",
      "\n",
      "--------------------------------------------------------------------------------\n",
      "1 fits failed with the following error:\n",
      "Traceback (most recent call last):\n",
      "  File \"c:\\Users\\PHIL\\AppData\\Local\\Programs\\Python\\Python312\\Lib\\site-packages\\sklearn\\model_selection\\_validation.py\", line 888, in _fit_and_score\n",
      "    estimator.fit(X_train, y_train, **fit_params)\n",
      "  File \"c:\\Users\\PHIL\\AppData\\Local\\Programs\\Python\\Python312\\Lib\\site-packages\\scikeras\\wrappers.py\", line 770, in fit\n",
      "    self._fit(\n",
      "  File \"c:\\Users\\PHIL\\AppData\\Local\\Programs\\Python\\Python312\\Lib\\site-packages\\scikeras\\wrappers.py\", line 938, in _fit\n",
      "    self._fit_keras_model(\n",
      "  File \"c:\\Users\\PHIL\\AppData\\Local\\Programs\\Python\\Python312\\Lib\\site-packages\\scikeras\\wrappers.py\", line 535, in _fit_keras_model\n",
      "    hist = self.model_.fit(x=X, y=y, **fit_args)\n",
      "           ^^^^^^^^^^^^^^^^^^^^^^^^^^^^^^^^^^^^^\n",
      "  File \"c:\\Users\\PHIL\\AppData\\Local\\Programs\\Python\\Python312\\Lib\\site-packages\\keras\\src\\utils\\traceback_utils.py\", line 122, in error_handler\n",
      "    raise e.with_traceback(filtered_tb) from None\n",
      "  File \"c:\\Users\\PHIL\\AppData\\Local\\Programs\\Python\\Python312\\Lib\\site-packages\\keras\\src\\utils\\traceback_utils.py\", line 124, in error_handler\n",
      "    del filtered_tb\n",
      "        ^^^^^^^^^^^\n",
      "ValueError: Exception encountered when calling Conv1D.call().\n",
      "\n",
      "\u001b[1mNegative dimension size caused by subtracting 2 from 1 for '{{node sequential_5_1/conv1d_5_1/convolution}} = Conv2D[T=DT_FLOAT, data_format=\"NHWC\", dilations=[1, 1, 1, 1], explicit_paddings=[], padding=\"VALID\", strides=[1, 1, 1, 1], use_cudnn_on_gpu=true](sequential_5_1/conv1d_5_1/convolution/ExpandDims, sequential_5_1/conv1d_5_1/convolution/ExpandDims_1)' with input shapes: [?,1,1,3], [1,2,3,128].\u001b[0m\n",
      "\n",
      "Arguments received by Conv1D.call():\n",
      "  â€¢ inputs=tf.Tensor(shape=(None, 1, 3), dtype=float32)\n",
      "\n",
      "--------------------------------------------------------------------------------\n",
      "1 fits failed with the following error:\n",
      "Traceback (most recent call last):\n",
      "  File \"c:\\Users\\PHIL\\AppData\\Local\\Programs\\Python\\Python312\\Lib\\site-packages\\sklearn\\model_selection\\_validation.py\", line 888, in _fit_and_score\n",
      "    estimator.fit(X_train, y_train, **fit_params)\n",
      "  File \"c:\\Users\\PHIL\\AppData\\Local\\Programs\\Python\\Python312\\Lib\\site-packages\\scikeras\\wrappers.py\", line 770, in fit\n",
      "    self._fit(\n",
      "  File \"c:\\Users\\PHIL\\AppData\\Local\\Programs\\Python\\Python312\\Lib\\site-packages\\scikeras\\wrappers.py\", line 938, in _fit\n",
      "    self._fit_keras_model(\n",
      "  File \"c:\\Users\\PHIL\\AppData\\Local\\Programs\\Python\\Python312\\Lib\\site-packages\\scikeras\\wrappers.py\", line 535, in _fit_keras_model\n",
      "    hist = self.model_.fit(x=X, y=y, **fit_args)\n",
      "           ^^^^^^^^^^^^^^^^^^^^^^^^^^^^^^^^^^^^^\n",
      "  File \"c:\\Users\\PHIL\\AppData\\Local\\Programs\\Python\\Python312\\Lib\\site-packages\\keras\\src\\utils\\traceback_utils.py\", line 122, in error_handler\n",
      "    raise e.with_traceback(filtered_tb) from None\n",
      "  File \"c:\\Users\\PHIL\\AppData\\Local\\Programs\\Python\\Python312\\Lib\\site-packages\\keras\\src\\utils\\traceback_utils.py\", line 124, in error_handler\n",
      "    del filtered_tb\n",
      "        ^^^^^^^^^^^\n",
      "ValueError: Exception encountered when calling Conv1D.call().\n",
      "\n",
      "\u001b[1mNegative dimension size caused by subtracting 2 from 1 for '{{node sequential_9_1/conv1d_9_1/convolution}} = Conv2D[T=DT_FLOAT, data_format=\"NHWC\", dilations=[1, 1, 1, 1], explicit_paddings=[], padding=\"VALID\", strides=[1, 1, 1, 1], use_cudnn_on_gpu=true](sequential_9_1/conv1d_9_1/convolution/ExpandDims, sequential_9_1/conv1d_9_1/convolution/ExpandDims_1)' with input shapes: [?,1,1,3], [1,2,3,128].\u001b[0m\n",
      "\n",
      "Arguments received by Conv1D.call():\n",
      "  â€¢ inputs=tf.Tensor(shape=(None, 1, 3), dtype=float32)\n",
      "\n",
      "--------------------------------------------------------------------------------\n",
      "1 fits failed with the following error:\n",
      "Traceback (most recent call last):\n",
      "  File \"c:\\Users\\PHIL\\AppData\\Local\\Programs\\Python\\Python312\\Lib\\site-packages\\sklearn\\model_selection\\_validation.py\", line 888, in _fit_and_score\n",
      "    estimator.fit(X_train, y_train, **fit_params)\n",
      "  File \"c:\\Users\\PHIL\\AppData\\Local\\Programs\\Python\\Python312\\Lib\\site-packages\\scikeras\\wrappers.py\", line 770, in fit\n",
      "    self._fit(\n",
      "  File \"c:\\Users\\PHIL\\AppData\\Local\\Programs\\Python\\Python312\\Lib\\site-packages\\scikeras\\wrappers.py\", line 938, in _fit\n",
      "    self._fit_keras_model(\n",
      "  File \"c:\\Users\\PHIL\\AppData\\Local\\Programs\\Python\\Python312\\Lib\\site-packages\\scikeras\\wrappers.py\", line 535, in _fit_keras_model\n",
      "    hist = self.model_.fit(x=X, y=y, **fit_args)\n",
      "           ^^^^^^^^^^^^^^^^^^^^^^^^^^^^^^^^^^^^^\n",
      "  File \"c:\\Users\\PHIL\\AppData\\Local\\Programs\\Python\\Python312\\Lib\\site-packages\\keras\\src\\utils\\traceback_utils.py\", line 122, in error_handler\n",
      "    raise e.with_traceback(filtered_tb) from None\n",
      "  File \"c:\\Users\\PHIL\\AppData\\Local\\Programs\\Python\\Python312\\Lib\\site-packages\\keras\\src\\utils\\traceback_utils.py\", line 124, in error_handler\n",
      "    del filtered_tb\n",
      "        ^^^^^^^^^^^\n",
      "ValueError: Exception encountered when calling Conv1D.call().\n",
      "\n",
      "\u001b[1mNegative dimension size caused by subtracting 2 from 1 for '{{node sequential_10_1/conv1d_10_1/convolution}} = Conv2D[T=DT_FLOAT, data_format=\"NHWC\", dilations=[1, 1, 1, 1], explicit_paddings=[], padding=\"VALID\", strides=[1, 1, 1, 1], use_cudnn_on_gpu=true](sequential_10_1/conv1d_10_1/convolution/ExpandDims, sequential_10_1/conv1d_10_1/convolution/ExpandDims_1)' with input shapes: [?,1,1,3], [1,2,3,128].\u001b[0m\n",
      "\n",
      "Arguments received by Conv1D.call():\n",
      "  â€¢ inputs=tf.Tensor(shape=(None, 1, 3), dtype=float32)\n",
      "\n",
      "--------------------------------------------------------------------------------\n",
      "1 fits failed with the following error:\n",
      "Traceback (most recent call last):\n",
      "  File \"c:\\Users\\PHIL\\AppData\\Local\\Programs\\Python\\Python312\\Lib\\site-packages\\sklearn\\model_selection\\_validation.py\", line 888, in _fit_and_score\n",
      "    estimator.fit(X_train, y_train, **fit_params)\n",
      "  File \"c:\\Users\\PHIL\\AppData\\Local\\Programs\\Python\\Python312\\Lib\\site-packages\\scikeras\\wrappers.py\", line 770, in fit\n",
      "    self._fit(\n",
      "  File \"c:\\Users\\PHIL\\AppData\\Local\\Programs\\Python\\Python312\\Lib\\site-packages\\scikeras\\wrappers.py\", line 938, in _fit\n",
      "    self._fit_keras_model(\n",
      "  File \"c:\\Users\\PHIL\\AppData\\Local\\Programs\\Python\\Python312\\Lib\\site-packages\\scikeras\\wrappers.py\", line 535, in _fit_keras_model\n",
      "    hist = self.model_.fit(x=X, y=y, **fit_args)\n",
      "           ^^^^^^^^^^^^^^^^^^^^^^^^^^^^^^^^^^^^^\n",
      "  File \"c:\\Users\\PHIL\\AppData\\Local\\Programs\\Python\\Python312\\Lib\\site-packages\\keras\\src\\utils\\traceback_utils.py\", line 122, in error_handler\n",
      "    raise e.with_traceback(filtered_tb) from None\n",
      "  File \"c:\\Users\\PHIL\\AppData\\Local\\Programs\\Python\\Python312\\Lib\\site-packages\\keras\\src\\utils\\traceback_utils.py\", line 124, in error_handler\n",
      "    del filtered_tb\n",
      "        ^^^^^^^^^^^\n",
      "ValueError: Exception encountered when calling Conv1D.call().\n",
      "\n",
      "\u001b[1mNegative dimension size caused by subtracting 2 from 1 for '{{node sequential_11_1/conv1d_11_1/convolution}} = Conv2D[T=DT_FLOAT, data_format=\"NHWC\", dilations=[1, 1, 1, 1], explicit_paddings=[], padding=\"VALID\", strides=[1, 1, 1, 1], use_cudnn_on_gpu=true](sequential_11_1/conv1d_11_1/convolution/ExpandDims, sequential_11_1/conv1d_11_1/convolution/ExpandDims_1)' with input shapes: [?,1,1,3], [1,2,3,128].\u001b[0m\n",
      "\n",
      "Arguments received by Conv1D.call():\n",
      "  â€¢ inputs=tf.Tensor(shape=(None, 1, 3), dtype=float32)\n",
      "\n",
      "--------------------------------------------------------------------------------\n",
      "1 fits failed with the following error:\n",
      "Traceback (most recent call last):\n",
      "  File \"c:\\Users\\PHIL\\AppData\\Local\\Programs\\Python\\Python312\\Lib\\site-packages\\sklearn\\model_selection\\_validation.py\", line 888, in _fit_and_score\n",
      "    estimator.fit(X_train, y_train, **fit_params)\n",
      "  File \"c:\\Users\\PHIL\\AppData\\Local\\Programs\\Python\\Python312\\Lib\\site-packages\\scikeras\\wrappers.py\", line 770, in fit\n",
      "    self._fit(\n",
      "  File \"c:\\Users\\PHIL\\AppData\\Local\\Programs\\Python\\Python312\\Lib\\site-packages\\scikeras\\wrappers.py\", line 938, in _fit\n",
      "    self._fit_keras_model(\n",
      "  File \"c:\\Users\\PHIL\\AppData\\Local\\Programs\\Python\\Python312\\Lib\\site-packages\\scikeras\\wrappers.py\", line 535, in _fit_keras_model\n",
      "    hist = self.model_.fit(x=X, y=y, **fit_args)\n",
      "           ^^^^^^^^^^^^^^^^^^^^^^^^^^^^^^^^^^^^^\n",
      "  File \"c:\\Users\\PHIL\\AppData\\Local\\Programs\\Python\\Python312\\Lib\\site-packages\\keras\\src\\utils\\traceback_utils.py\", line 122, in error_handler\n",
      "    raise e.with_traceback(filtered_tb) from None\n",
      "  File \"c:\\Users\\PHIL\\AppData\\Local\\Programs\\Python\\Python312\\Lib\\site-packages\\keras\\src\\utils\\traceback_utils.py\", line 124, in error_handler\n",
      "    del filtered_tb\n",
      "        ^^^^^^^^^^^\n",
      "ValueError: Exception encountered when calling Conv1D.call().\n",
      "\n",
      "\u001b[1mNegative dimension size caused by subtracting 2 from 1 for '{{node sequential_12_1/conv1d_12_1/convolution}} = Conv2D[T=DT_FLOAT, data_format=\"NHWC\", dilations=[1, 1, 1, 1], explicit_paddings=[], padding=\"VALID\", strides=[1, 1, 1, 1], use_cudnn_on_gpu=true](sequential_12_1/conv1d_12_1/convolution/ExpandDims, sequential_12_1/conv1d_12_1/convolution/ExpandDims_1)' with input shapes: [?,1,1,3], [1,2,3,128].\u001b[0m\n",
      "\n",
      "Arguments received by Conv1D.call():\n",
      "  â€¢ inputs=tf.Tensor(shape=(None, 1, 3), dtype=float32)\n",
      "\n",
      "--------------------------------------------------------------------------------\n",
      "1 fits failed with the following error:\n",
      "Traceback (most recent call last):\n",
      "  File \"c:\\Users\\PHIL\\AppData\\Local\\Programs\\Python\\Python312\\Lib\\site-packages\\sklearn\\model_selection\\_validation.py\", line 888, in _fit_and_score\n",
      "    estimator.fit(X_train, y_train, **fit_params)\n",
      "  File \"c:\\Users\\PHIL\\AppData\\Local\\Programs\\Python\\Python312\\Lib\\site-packages\\scikeras\\wrappers.py\", line 770, in fit\n",
      "    self._fit(\n",
      "  File \"c:\\Users\\PHIL\\AppData\\Local\\Programs\\Python\\Python312\\Lib\\site-packages\\scikeras\\wrappers.py\", line 938, in _fit\n",
      "    self._fit_keras_model(\n",
      "  File \"c:\\Users\\PHIL\\AppData\\Local\\Programs\\Python\\Python312\\Lib\\site-packages\\scikeras\\wrappers.py\", line 535, in _fit_keras_model\n",
      "    hist = self.model_.fit(x=X, y=y, **fit_args)\n",
      "           ^^^^^^^^^^^^^^^^^^^^^^^^^^^^^^^^^^^^^\n",
      "  File \"c:\\Users\\PHIL\\AppData\\Local\\Programs\\Python\\Python312\\Lib\\site-packages\\keras\\src\\utils\\traceback_utils.py\", line 122, in error_handler\n",
      "    raise e.with_traceback(filtered_tb) from None\n",
      "  File \"c:\\Users\\PHIL\\AppData\\Local\\Programs\\Python\\Python312\\Lib\\site-packages\\keras\\src\\utils\\traceback_utils.py\", line 124, in error_handler\n",
      "    del filtered_tb\n",
      "        ^^^^^^^^^^^\n",
      "ValueError: Exception encountered when calling Conv1D.call().\n",
      "\n",
      "\u001b[1mNegative dimension size caused by subtracting 2 from 1 for '{{node sequential_13_1/conv1d_13_1/convolution}} = Conv2D[T=DT_FLOAT, data_format=\"NHWC\", dilations=[1, 1, 1, 1], explicit_paddings=[], padding=\"VALID\", strides=[1, 1, 1, 1], use_cudnn_on_gpu=true](sequential_13_1/conv1d_13_1/convolution/ExpandDims, sequential_13_1/conv1d_13_1/convolution/ExpandDims_1)' with input shapes: [?,1,1,3], [1,2,3,128].\u001b[0m\n",
      "\n",
      "Arguments received by Conv1D.call():\n",
      "  â€¢ inputs=tf.Tensor(shape=(None, 1, 3), dtype=float32)\n",
      "\n",
      "--------------------------------------------------------------------------------\n",
      "1 fits failed with the following error:\n",
      "Traceback (most recent call last):\n",
      "  File \"c:\\Users\\PHIL\\AppData\\Local\\Programs\\Python\\Python312\\Lib\\site-packages\\sklearn\\model_selection\\_validation.py\", line 888, in _fit_and_score\n",
      "    estimator.fit(X_train, y_train, **fit_params)\n",
      "  File \"c:\\Users\\PHIL\\AppData\\Local\\Programs\\Python\\Python312\\Lib\\site-packages\\scikeras\\wrappers.py\", line 770, in fit\n",
      "    self._fit(\n",
      "  File \"c:\\Users\\PHIL\\AppData\\Local\\Programs\\Python\\Python312\\Lib\\site-packages\\scikeras\\wrappers.py\", line 938, in _fit\n",
      "    self._fit_keras_model(\n",
      "  File \"c:\\Users\\PHIL\\AppData\\Local\\Programs\\Python\\Python312\\Lib\\site-packages\\scikeras\\wrappers.py\", line 535, in _fit_keras_model\n",
      "    hist = self.model_.fit(x=X, y=y, **fit_args)\n",
      "           ^^^^^^^^^^^^^^^^^^^^^^^^^^^^^^^^^^^^^\n",
      "  File \"c:\\Users\\PHIL\\AppData\\Local\\Programs\\Python\\Python312\\Lib\\site-packages\\keras\\src\\utils\\traceback_utils.py\", line 122, in error_handler\n",
      "    raise e.with_traceback(filtered_tb) from None\n",
      "  File \"c:\\Users\\PHIL\\AppData\\Local\\Programs\\Python\\Python312\\Lib\\site-packages\\keras\\src\\utils\\traceback_utils.py\", line 124, in error_handler\n",
      "    del filtered_tb\n",
      "        ^^^^^^^^^^^\n",
      "ValueError: Exception encountered when calling Conv1D.call().\n",
      "\n",
      "\u001b[1mNegative dimension size caused by subtracting 2 from 1 for '{{node sequential_14_1/conv1d_14_1/convolution}} = Conv2D[T=DT_FLOAT, data_format=\"NHWC\", dilations=[1, 1, 1, 1], explicit_paddings=[], padding=\"VALID\", strides=[1, 1, 1, 1], use_cudnn_on_gpu=true](sequential_14_1/conv1d_14_1/convolution/ExpandDims, sequential_14_1/conv1d_14_1/convolution/ExpandDims_1)' with input shapes: [?,1,1,3], [1,2,3,128].\u001b[0m\n",
      "\n",
      "Arguments received by Conv1D.call():\n",
      "  â€¢ inputs=tf.Tensor(shape=(None, 1, 3), dtype=float32)\n",
      "\n",
      "  warnings.warn(some_fits_failed_message, FitFailedWarning)\n",
      "c:\\Users\\PHIL\\AppData\\Local\\Programs\\Python\\Python312\\Lib\\site-packages\\sklearn\\model_selection\\_search.py:1103: UserWarning: One or more of the test scores are non-finite: [         nan          nan -13.68566017          nan          nan]\n",
      "  warnings.warn(\n",
      "c:\\Users\\PHIL\\AppData\\Local\\Programs\\Python\\Python312\\Lib\\site-packages\\keras\\src\\layers\\convolutional\\base_conv.py:107: UserWarning: Do not pass an `input_shape`/`input_dim` argument to a layer. When using Sequential models, prefer using an `Input(shape)` object as the first layer in the model instead.\n",
      "  super().__init__(activity_regularizer=activity_regularizer, **kwargs)\n",
      "WARNING:absl:You are saving your model as an HDF5 file via `model.save()` or `keras.saving.save_model(model)`. This file format is considered legacy. We recommend using instead the native Keras format, e.g. `model.save('my_model.keras')` or `keras.saving.save_model(model, 'my_model.keras')`. \n"
     ]
    },
    {
     "name": "stdout",
     "output_type": "stream",
     "text": [
      "Best Parameters: {'model__learning_rate': 0.001, 'model__kernel_size': 1, 'model__filters': 128, 'model__dense_units': 32, 'epochs': 30, 'batch_size': 32}\n",
      "Model and scaler saved successfully.\n"
     ]
    }
   ],
   "source": [
    "import pandas as pd\n",
    "import numpy as np\n",
    "from sklearn.model_selection import KFold, RandomizedSearchCV\n",
    "from sklearn.preprocessing import MinMaxScaler\n",
    "from sklearn.metrics import mean_squared_error\n",
    "from scikeras.wrappers import KerasRegressor\n",
    "from keras.models import Sequential\n",
    "from keras.layers import Conv1D, Flatten, Dense\n",
    "from keras.optimizers import Adam\n",
    "from keras.callbacks import EarlyStopping\n",
    "import joblib\n",
    "\n",
    "# -----------------------------\n",
    "# Load and preprocess the data\n",
    "# -----------------------------\n",
    "# Load dataset\n",
    "df = pd.read_csv(r\"C:\\ML_work\\Data Engineering work\\uasin_gishu_weather_data.csv\", parse_dates=[\"time\"])\n",
    "\n",
    "# Sort by date\n",
    "df = df.sort_values(by='time')\n",
    "\n",
    "# Features and target\n",
    "features = ['temperature_2m_max', 'temperature_2m_min', 'windspeed_10m_max']\n",
    "target = 'precipitation_sum'\n",
    "\n",
    "# Check for missing values and fill them with column mean\n",
    "df[features + [target]] = df[features + [target]].fillna(df[features + [target]].mean())\n",
    "\n",
    "# Extract input and output\n",
    "X = df[features].values\n",
    "y = df[target].values\n",
    "\n",
    "# Normalize features\n",
    "scaler = MinMaxScaler()\n",
    "X_scaled = scaler.fit_transform(X)\n",
    "\n",
    "# Reshape input for CNN: (samples, timesteps, features)\n",
    "X_scaled = X_scaled.reshape((X_scaled.shape[0], 1, X_scaled.shape[1]))\n",
    "\n",
    "# -----------------------------\n",
    "# Build CNN model function\n",
    "# -----------------------------\n",
    "def build_model(filters=64, kernel_size=2, dense_units=32, learning_rate=0.001, input_shape=(1, 3)):\n",
    "    model = Sequential()\n",
    "    model.add(Conv1D(filters=filters, kernel_size=kernel_size, activation='relu', input_shape=input_shape))\n",
    "    model.add(Flatten())\n",
    "    model.add(Dense(dense_units, activation='relu'))\n",
    "    model.add(Dense(1))  # Output layer\n",
    "    model.compile(optimizer=Adam(learning_rate=learning_rate), loss='mse')\n",
    "    return model\n",
    "\n",
    "# -----------------------------\n",
    "# Wrap model for scikit-learn\n",
    "# -----------------------------\n",
    "regressor = KerasRegressor(\n",
    "    model=build_model,\n",
    "    model__input_shape=(X_scaled.shape[1], X_scaled.shape[2]),\n",
    "    verbose=0\n",
    ")\n",
    "\n",
    "# -----------------------------\n",
    "# Hyperparameter space\n",
    "# -----------------------------\n",
    "param_dist = {\n",
    "    'model__filters': [32, 64, 128],\n",
    "    'model__kernel_size': [1, 2, 3],\n",
    "    'model__dense_units': [16, 32, 64],\n",
    "    'model__learning_rate': [0.001, 0.0001],\n",
    "    'batch_size': [16, 32],\n",
    "    'epochs': [30, 50]\n",
    "}\n",
    "\n",
    "# -----------------------------\n",
    "# Cross-validation and search\n",
    "# -----------------------------\n",
    "kfold = KFold(n_splits=3, shuffle=True, random_state=42)\n",
    "\n",
    "random_search = RandomizedSearchCV(\n",
    "    estimator=regressor,\n",
    "    param_distributions=param_dist,\n",
    "    cv=kfold,\n",
    "    n_iter=5,\n",
    "    scoring='neg_mean_squared_error',\n",
    "    random_state=42\n",
    ")\n",
    "\n",
    "early_stop = EarlyStopping(monitor='loss', patience=5, restore_best_weights=True)\n",
    "\n",
    "# -----------------------------\n",
    "# Train the model\n",
    "# -----------------------------\n",
    "random_search.fit(X_scaled, y, callbacks=[early_stop])\n",
    "\n",
    "print(\"Best Parameters:\", random_search.best_params_)\n",
    "\n",
    "# -----------------------------\n",
    "# Save best model and scaler\n",
    "# -----------------------------\n",
    "best_model = random_search.best_estimator_.model_\n",
    "best_model.save(\"cnn_weather_model.h5\")\n",
    "\n",
    "joblib.dump(scaler, \"weather_scaler.pkl\")\n",
    "\n",
    "print(\"Model and scaler saved successfully.\")\n"
   ]
  }
 ],
 "metadata": {
  "kernelspec": {
   "display_name": "Python 3",
   "language": "python",
   "name": "python3"
  },
  "language_info": {
   "codemirror_mode": {
    "name": "ipython",
    "version": 3
   },
   "file_extension": ".py",
   "mimetype": "text/x-python",
   "name": "python",
   "nbconvert_exporter": "python",
   "pygments_lexer": "ipython3",
   "version": "3.12.6"
  }
 },
 "nbformat": 4,
 "nbformat_minor": 5
}
